Watching for file changes with StatReloader
Watching for file changes with StatReloader
/home/ubuntu/DjangoDemo/DjangoLogin/settings.py changed, reloading.
Performing system checks...

System check identified no issues (0 silenced).
February 17, 2022 - 17:21:02
Django version 3.2.12, using settings 'DjangoLogin.settings'
Starting development server at http://127.0.0.1:8000/
Quit the server with CONTROL-C.
Watching for file changes with StatReloader
Traceback (most recent call last):
  File "/home/ubuntu/DjangoDemo/DjangoLogin/settings.py", line 26, in <module>
    SECRET_KEY = os.environ["SECRET_KEY"]
  File "/usr/lib/python3.6/os.py", line 669, in __getitem__
    raise KeyError(key) from None
KeyError: 'SECRET_KEY'

The above exception was the direct cause of the following exception:

Traceback (most recent call last):
  File "manage.py", line 22, in <module>
    main()
  File "manage.py", line 18, in main
    execute_from_command_line(sys.argv)
  File "/home/ubuntu/venv/lib/python3.6/site-packages/django/core/management/__init__.py", line 419, in execute_from_command_line
    utility.execute()
  File "/home/ubuntu/venv/lib/python3.6/site-packages/django/core/management/__init__.py", line 363, in execute
    settings.INSTALLED_APPS
  File "/home/ubuntu/venv/lib/python3.6/site-packages/django/conf/__init__.py", line 82, in __getattr__
    self._setup(name)
  File "/home/ubuntu/venv/lib/python3.6/site-packages/django/conf/__init__.py", line 69, in _setup
    self._wrapped = Settings(settings_module)
  File "/home/ubuntu/venv/lib/python3.6/site-packages/django/conf/__init__.py", line 170, in __init__
    mod = importlib.import_module(self.SETTINGS_MODULE)
  File "/usr/lib/python3.6/importlib/__init__.py", line 126, in import_module
    return _bootstrap._gcd_import(name[level:], package, level)
  File "<frozen importlib._bootstrap>", line 994, in _gcd_import
  File "<frozen importlib._bootstrap>", line 971, in _find_and_load
  File "<frozen importlib._bootstrap>", line 955, in _find_and_load_unlocked
  File "<frozen importlib._bootstrap>", line 665, in _load_unlocked
  File "<frozen importlib._bootstrap_external>", line 678, in exec_module
  File "<frozen importlib._bootstrap>", line 219, in _call_with_frames_removed
  File "/home/ubuntu/DjangoDemo/DjangoLogin/settings.py", line 28, in <module>
    raise RuntimeError("Couldnt find a secret key in environment") from e
RuntimeError: Couldnt find a secret key in environment
/home/ubuntu/DjangoDemo/DjangoLogin/settings.py changed, reloading.
Performing system checks...

System check identified no issues (0 silenced).
February 17, 2022 - 17:42:38
Django version 3.2.12, using settings 'DjangoLogin.settings'
Starting development server at http://127.0.0.1:8000/
Quit the server with CONTROL-C.
Watching for file changes with StatReloader
